# 🎯 Proto 导入问题终极修复

## 问题总结

发现了 **2个关键Bug**：

### Bug 1: `__init__.py` 静默吞掉错误
```python
# ❌ 错误的代码
try:
    from . import clouddrive_pb2
    from . import clouddrive_pb2_grpc
    __all__ = ['clouddrive_pb2', 'clouddrive_pb2_grpc']
except ImportError:
    pass  # 静默失败！
```

**问题**：
- 导入失败时不抛出错误
- 导致后续代码以为导入成功了
- 实际使用时才报 `No module named 'clouddrive_pb2'`

**修复**：
```python
# ✅ 正确的代码
from . import clouddrive_pb2
from . import clouddrive_pb2_grpc
__all__ = ['clouddrive_pb2', 'clouddrive_pb2_grpc']
```

### Bug 2: `clouddrive_pb2_grpc.py` 使用绝对导入
```python
# ❌ grpc_tools.protoc 生成的代码
import clouddrive_pb2 as clouddrive__pb2
```

**问题**：
- 在包内导入时找不到 `clouddrive_pb2` 模块
- 因为它应该用相对导入 `from . import clouddrive_pb2`

**修复**：
`generate_grpc_clouddrive.py` 中的 `fix_imports()` 函数会自动修复：
```python
content = content.replace(
    'import clouddrive_pb2 as clouddrive__pb2',
    'from . import clouddrive_pb2 as clouddrive__pb2'
)
```

## 修复历史

1. **26分钟前**: 修复 `sys.path` 设置
2. **13分钟前**: 增强诊断日志
3. **5分钟前**: 修复 `.dockerignore` 的 `*.py[cod]` 问题
4. **刚刚**: 修复 `__init__.py` 和重新生成 proto 文件

## 验证

### 本地测试
```bash
$ cd app/backend
$ python -c "import sys; sys.path.insert(0, '.'); from protos import clouddrive_pb2; print('SUCCESS')"
SUCCESS
```

✅ **本地导入成功！**

### Docker 测试

等待 GitHub Actions 构建完成（约 5-10 分钟），然后：

```bash
# 1. 强制更新镜像
docker-compose down
docker rmi hav93/tmc:test -f
docker-compose pull
docker-compose up -d

# 2. 验证
docker exec tmc python -c "import sys; sys.path.insert(0, '/app'); from protos import clouddrive_pb2; print('SUCCESS')"
```

应该看到：
```
SUCCESS
```

而不是：
```
ModuleNotFoundError: No module named 'clouddrive_pb2'
```

## 预期结果

上传时的日志应该从：
```
⚠️ 官方 proto 不可用，将使用 HTTP 备选方案
   详细错误: 无法导入 proto 文件。尝试1: No module named 'clouddrive_pb2', 尝试2: No module named 'clouddrive_pb2'
```

变成：
```
✅ 官方 proto 可用 (从 protos 包)
```

然后上传应该能够正常工作！

## 关键改进

1. ✅ 修复了 proto 导入路径（相对导入）
2. ✅ 移除了静默错误处理
3. ✅ 修复了 `.dockerignore` 阻止 `.py` 文件
4. ✅ 清理 Docker buildx 缓存
5. ✅ 增强了诊断日志

## 时间线

- 13:55 - 用户报告错误没变化
- 14:03 - 看到详细错误信息
- 14:10 - 发现 `.dockerignore` 问题
- 14:15 - 用户指出 GitHub 可能用了旧路径
- 14:18 - **发现 `__init__.py` 和 import 问题**
- 14:20 - **修复完成，本地验证成功**

---

**这次真的修复了核心问题！** 🎉

